<robot name="simple_arm">
    <link name="base_link">
        <visual>
            <geometry><cylinder radius="0.1" length="0.2"/></geometry>
            <material name="silver"><color rgba="0.7 0.7 0.7 1.0"/></material>
        </visual>
        <collision></geometry><cylinder radius="0.1" length="0.2"/></geometry></collision>
        <inertial><mass value="1.0"/><inertia ixx="0.01" ixy="0.0" ixz="0.0" iyy="0.01" iyz="0.0" izz="0.01"/></inertial>
    </link>
    <link name="upper_arm">
        <visual>
            <geometry><cylinder radius="0.05" length="0.4"/></geometry>
            <material name="silver"/>
        </visual>
        <collision><geometry><cylinder radius "0.05" length="0.4"/></geometry></collision>
        <inertial><mass value="0.5"/><inertia ixx="0.005" ixy="0.0" ixz="0.0" iyy="0.005" iyz="0.0" izz="0.005"/></inertial>
    </link>
    <joint name="base_to_upper" type="revolute">
        <parent link="base_link"/>
        <child link="upper_arm"/>
        <origin xyz="0 0 0.2" rpy="0 0 0"/>
        <axis xyz="0 0 1"/>
        <limit lower="-3.14" upper="3.14" effort="10" velocity="1"/>
    </joint>
</robot>
